<!--ジョイントに関するマクロファイル-->
<?xml version="1.0"?>
<robot xmlns:xacro="http://ros.org/wiki/xacro">

<xacro:macro name="fixed_joint" params="name parent child *origin">

	<joint name="${name}" type="fixed">
    <xacro:insert_block name="origin" />
    <parent link="${parent}"/>
    <child link="${child}"/>
 	</joint>

</xacro:macro>

<xacro:macro name="continuous_joint" params="name parent child *origin *axis">

	<joint name="${name}" type="continuous">
    <xacro:insert_block name="origin" />
    <parent link="${parent}"/>
    <child link="${child}"/>
    <xacro:insert_block name="axis" />
 	</joint>

</xacro:macro>

</robot>
